<?xml version="1.0" ?>
<!-- =================================================================================== -->
<!-- |    This document was autogenerated by xacro from src/Assembly_description_2/urdf/Assembly.xacro | -->
<!-- |    EDITING THIS FILE BY HAND IS NOT RECOMMENDED                                 | -->
<!-- =================================================================================== -->
<robot name="Assembly">
  <material name="silver">
    <color rgba="0.700 0.700 0.700 1.000"/>
  </material>
  <material name="black">
    <color rgba="0.2 0.2 0.2 1."/>
  </material>
  <material name="blue">
    <color rgba="0.3 0.57 1. 1."/>
  </material>
  <transmission name="Revolute_40_tran">
    <type>transmission_interface/SimpleTransmission</type>
    <joint name="Revolute_40">
      <hardwareInterface>hardware_interface/EffortJointInterface</hardwareInterface>
    </joint>
    <actuator name="Revolute_40_actr">
      <hardwareInterface>hardware_interface/EffortJointInterface</hardwareInterface>
      <mechanicalReduction>1</mechanicalReduction>
    </actuator>
  </transmission>
  <transmission name="Revolute_41_tran">
    <type>transmission_interface/SimpleTransmission</type>
    <joint name="Revolute_41">
      <hardwareInterface>hardware_interface/EffortJointInterface</hardwareInterface>
    </joint>
    <actuator name="Revolute_41_actr">
      <hardwareInterface>hardware_interface/EffortJointInterface</hardwareInterface>
      <mechanicalReduction>1</mechanicalReduction>
    </actuator>
  </transmission>
  <transmission name="Revolute_42_tran">
    <type>transmission_interface/SimpleTransmission</type>
    <joint name="Revolute_42">
      <hardwareInterface>hardware_interface/EffortJointInterface</hardwareInterface>
    </joint>
    <actuator name="Revolute_42_actr">
      <hardwareInterface>hardware_interface/EffortJointInterface</hardwareInterface>
      <mechanicalReduction>1</mechanicalReduction>
    </actuator>
  </transmission>
  <transmission name="Revolute_43_tran">
    <type>transmission_interface/SimpleTransmission</type>
    <joint name="Revolute_43">
      <hardwareInterface>hardware_interface/EffortJointInterface</hardwareInterface>
    </joint>
    <actuator name="Revolute_43_actr">
      <hardwareInterface>hardware_interface/EffortJointInterface</hardwareInterface>
      <mechanicalReduction>1</mechanicalReduction>
    </actuator>
  </transmission>
  <transmission name="Revolute_44_tran">
    <type>transmission_interface/SimpleTransmission</type>
    <joint name="Revolute_44">
      <hardwareInterface>hardware_interface/EffortJointInterface</hardwareInterface>
    </joint>
    <actuator name="Revolute_44_actr">
      <hardwareInterface>hardware_interface/EffortJointInterface</hardwareInterface>
      <mechanicalReduction>1</mechanicalReduction>
    </actuator>
  </transmission>
  <transmission name="Revolute_45_tran">
    <type>transmission_interface/SimpleTransmission</type>
    <joint name="Revolute_45">
      <hardwareInterface>hardware_interface/EffortJointInterface</hardwareInterface>
    </joint>
    <actuator name="Revolute_45_actr">
      <hardwareInterface>hardware_interface/EffortJointInterface</hardwareInterface>
      <mechanicalReduction>1</mechanicalReduction>
    </actuator>
  </transmission>
  <gazebo>
    <plugin filename="libgazebo_ros_control.so" name="control"/>
  </gazebo>
  <gazebo reference="base_link">
    <material>Gazebo/Silver</material>
    <mu1>0.2</mu1>
    <mu2>0.2</mu2>
    <selfCollide>true</selfCollide>
    <gravity>true</gravity>
  </gazebo>
  <gazebo reference="rotator_left_1">
    <material>Gazebo/Silver</material>
    <mu1>0.2</mu1>
    <mu2>0.2</mu2>
    <selfCollide>true</selfCollide>
  </gazebo>
  <gazebo reference="rotator_right_1">
    <material>Gazebo/Silver</material>
    <mu1>0.2</mu1>
    <mu2>0.2</mu2>
    <selfCollide>true</selfCollide>
  </gazebo>
  <gazebo reference="wheel_back_left_1">
    <material>Gazebo/Silver</material>
    <mu1>0.2</mu1>
    <mu2>0.2</mu2>
    <selfCollide>true</selfCollide>
  </gazebo>
  <gazebo reference="wheel_back_right_1">
    <material>Gazebo/Silver</material>
    <mu1>0.2</mu1>
    <mu2>0.2</mu2>
    <selfCollide>true</selfCollide>
  </gazebo>
  <gazebo reference="wheel_front_left_1">
    <material>Gazebo/Silver</material>
    <mu1>0.2</mu1>
    <mu2>0.2</mu2>
    <selfCollide>true</selfCollide>
  </gazebo>
  <gazebo reference="wheel_front_right_1">
    <material>Gazebo/Silver</material>
    <mu1>0.2</mu1>
    <mu2>0.2</mu2>
    <selfCollide>true</selfCollide>
  </gazebo>
  <link name="base_link">
    <inertial>
      <origin rpy="0 0 0" xyz="-0.02572645957604468 6.569516383123642e-06 0.017821626738037458"/>
      <mass value="4.156457046473223"/>
      <inertia ixx="0.013034" ixy="-6e-06" ixz="0.000867" iyy="0.084094" iyz="0.0" izz="0.095033"/>
    </inertial>
    <visual>
      <origin rpy="0 0 0" xyz="0 0 0"/>
      <geometry>
        <mesh filename="meshes/base_link.stl" scale="0.001 0.001 0.001"/>
      </geometry>
      <material name="silver"/>
    </visual>
    <collision>
      <origin rpy="0 0 0" xyz="0 0 0"/>
      <geometry>
        <mesh filename="meshes/base_link.stl" scale="0.001 0.001 0.001"/>
      </geometry>
    </collision>
  </link>
  <link name="rotator_left_1">
    <inertial>
      <origin rpy="0 0 0" xyz="4.4846516666918745e-07 0.003934914786975843 0.018000014002886432"/>
      <mass value="0.09154101472024741"/>
      <inertia ixx="1.1e-05" ixy="0.0" ixz="0.0" iyy="7e-06" iyz="0.0" izz="1e-05"/>
    </inertial>
    <visual>
      <origin rpy="0 0 0" xyz="-0.194799 -0.123074 -0.008"/>
      <geometry>
        <mesh filename="meshes/rotator_left_1.stl" scale="0.001 0.001 0.001"/>
      </geometry>
      <material name="silver"/>
    </visual>
    <collision>
      <origin rpy="0 0 0" xyz="-0.194799 -0.123074 -0.008"/>
      <geometry>
        <mesh filename="meshes/rotator_left_1.stl" scale="0.001 0.001 0.001"/>
      </geometry>
    </collision>
  </link>
  <link name="rotator_right_1">
    <inertial>
      <origin rpy="0 0 0" xyz="4.4867377607671344e-07 -0.0039356889065224054 0.018000014002296498"/>
      <mass value="0.0915410147202475"/>
      <inertia ixx="1.1e-05" ixy="-0.0" ixz="0.0" iyy="7e-06" iyz="-0.0" izz="1e-05"/>
    </inertial>
    <visual>
      <origin rpy="0 0 0" xyz="-0.194799 0.122975 -0.008"/>
      <geometry>
        <mesh filename="meshes/rotator_right_1.stl" scale="0.001 0.001 0.001"/>
      </geometry>
      <material name="silver"/>
    </visual>
    <collision>
      <origin rpy="0 0 0" xyz="-0.194799 0.122975 -0.008"/>
      <geometry>
        <mesh filename="meshes/rotator_right_1.stl" scale="0.001 0.001 0.001"/>
      </geometry>
    </collision>
  </link>
  <link name="wheel_back_left_1">
    <inertial>
      <origin rpy="0 0 0" xyz="-5.9590334083869934e-08 -0.004873834232398622 -1.6533018565301205e-09"/>
      <mass value="1.8001224559704576"/>
      <inertia ixx="0.001935" ixy="0.0" ixz="0.0" iyy="0.003387" iyz="-0.0" izz="0.001935"/>
    </inertial>
    <visual>
      <origin rpy="0 0 0" xyz="0.170156 -0.1398 -0.0205"/>
      <geometry>
        <mesh filename="meshes/wheel_back_left_1.stl" scale="0.001 0.001 0.001"/>
      </geometry>
      <material name="silver"/>
    </visual>
    <collision>
      <origin rpy="0 0 0" xyz="0.170156 -0.1398 -0.0205"/>
      <geometry>
        <mesh filename="meshes/wheel_back_left_1.stl" scale="0.001 0.001 0.001"/>
      </geometry>
    </collision>
  </link>
  <link name="wheel_back_right_1">
    <inertial>
      <origin rpy="0 0 0" xyz="-5.938171759867217e-08 0.004873835811921301 1.7874123604821879e-09"/>
      <mass value="1.8001224559704576"/>
      <inertia ixx="0.001935" ixy="-0.0" ixz="-0.0" iyy="0.003387" iyz="-0.0" izz="0.001935"/>
    </inertial>
    <visual>
      <origin rpy="0 0 0" xyz="0.170156 0.1398 -0.0205"/>
      <geometry>
        <mesh filename="meshes/wheel_back_right_1.stl" scale="0.001 0.001 0.001"/>
      </geometry>
      <material name="silver"/>
    </visual>
    <collision>
      <origin rpy="0 0 0" xyz="0.170156 0.1398 -0.0205"/>
      <geometry>
        <mesh filename="meshes/wheel_back_right_1.stl" scale="0.001 0.001 0.001"/>
      </geometry>
    </collision>
  </link>
  <link name="wheel_front_left_1">
    <inertial>
      <origin rpy="0 0 0" xyz="4.07839516408659e-07 -0.004874166721957063 -1.6533018461217797e-09"/>
      <mass value="1.8001224559704576"/>
      <inertia ixx="0.001935" ixy="0.0" ixz="0.0" iyy="0.003387" iyz="-0.0" izz="0.001935"/>
    </inertial>
    <visual>
      <origin rpy="0 0 0" xyz="-0.194799 -0.144374 -0.026"/>
      <geometry>
        <mesh filename="meshes/wheel_front_left_1.stl" scale="0.001 0.001 0.001"/>
      </geometry>
      <material name="silver"/>
    </visual>
    <collision>
      <origin rpy="0 0 0" xyz="-0.194799 -0.144374 -0.026"/>
      <geometry>
        <mesh filename="meshes/wheel_front_left_1.stl" scale="0.001 0.001 0.001"/>
      </geometry>
    </collision>
  </link>
  <link name="wheel_front_right_1">
    <inertial>
      <origin rpy="0 0 0" xyz="4.08048126010474e-07 0.0048733926024102925 1.7874124749739373e-09"/>
      <mass value="1.8001224559704576"/>
      <inertia ixx="0.001935" ixy="-0.0" ixz="-0.0" iyy="0.003387" iyz="-0.0" izz="0.001935"/>
    </inertial>
    <visual>
      <origin rpy="0 0 0" xyz="-0.194799 0.144275 -0.026"/>
      <geometry>
        <mesh filename="meshes/wheel_front_right_1.stl" scale="0.001 0.001 0.001"/>
      </geometry>
      <material name="silver"/>
    </visual>
    <collision>
      <origin rpy="0 0 0" xyz="-0.194799 0.144275 -0.026"/>
      <geometry>
        <mesh filename="meshes/wheel_front_right_1.stl" scale="0.001 0.001 0.001"/>
      </geometry>
    </collision>
  </link>
  <link name="hokuyo_1">
    <inertial>
      <origin rpy="0 0 0" xyz="0.24350755184543652 0.1300039563861765 0.029712797831224984"/>
      <mass value="0.36783477848639723"/>
      <inertia ixx="0.0002" ixy="0.0" ixz="1e-06" iyy="0.000206" iyz="0.0" izz="0.000127"/>
    </inertial>
    <visual>
      <origin rpy="0 0 0" xyz="0.128416 0.13 -0.038"/>
      <geometry>
        <mesh filename="meshes/hokuyo_1.stl" scale="0.001 0.001 0.001"/>
      </geometry>
      <material name="silver"/>
    </visual>
    <collision>
      <origin rpy="0 0 0" xyz="0.128416 0.13 -0.038"/>
      <geometry>
        <mesh filename="meshes/hokuyo_1.stl" scale="0.001 0.001 0.001"/>
      </geometry>
    </collision>
  </link>
  <joint name="left_wheel_rotator" type="continuous">
    <origin rpy="0 0 0" xyz="0.194799 0.123074 0.008"/>
    <parent link="base_link"/>
    <child link="rotator_left_1"/>
    <axis xyz="0.0 -0.0 1.0"/>
  </joint>
  <joint name="right_wheel_rotator" type="continuous">
    <origin rpy="0 0 0" xyz="0.194799 -0.122975 0.008"/>
    <parent link="base_link"/>
    <child link="rotator_right_1"/>
    <axis xyz="-0.0 -0.0 -1.0"/>
  </joint>
  <joint name="left_wheel_back" type="continuous">
    <origin rpy="0 0 0" xyz="-0.170156 0.1398 0.0205"/>
    <parent link="base_link"/>
    <child link="wheel_back_left_1"/>
    <axis xyz="0.0 1.0 0.0"/>
  </joint>
  <joint name="right_wheel_back" type="continuous">
    <origin rpy="0 0 0" xyz="-0.170156 -0.1398 0.0205"/>
    <parent link="base_link"/>
    <child link="wheel_back_right_1"/>
    <axis xyz="-0.0 -1.0 0.0"/>
  </joint>
  <joint name="left_wheel_front" type="continuous">
    <origin rpy="0 0 0" xyz="0.0 0.0213 0.018"/>
    <parent link="rotator_left_1"/>
    <child link="wheel_front_left_1"/>
    <axis xyz="0.0 1.0 0.0"/>
  </joint>
  <joint name="right_wheel_front" type="continuous">
    <origin rpy="0 0 0" xyz="0.0 -0.0213 0.018"/>
    <parent link="rotator_right_1"/>
    <child link="wheel_front_right_1"/>
    <axis xyz="-0.0 -1.0 -0.0"/>
  </joint>
  <joint name="Rigid 51" type="fixed">
    <origin rpy="0 0 0" xyz="-0.128416 -0.13 0.038"/>
    <parent link="base_link"/>
    <child link="hokuyo_1"/>
  </joint>
</robot>

